<?xml version="1.0"?>

<!-- This URDF was automatically created by SolidWorks to URDF Exporter! Originally created by Stephen Brawner (brawner@gmail.com) 
     Commit Version: 1.6.0-4-g7f85cfe  Build Version: 1.6.7995.38578
     For more information, please see http://wiki.ros.org/sw_urdf_exporter -->
<robot name='RG52_050' xmlns:xacro="http://www.ros.org/wiki/xacro">

    <link name="gripper_base_link">
        <inertial>
            <origin
                xyz="-1.9609E-07 0.0008592 0.048373"
                rpy="0 0 0" />
            <mass
                value="0.37215" />
            <inertia
                ixx="0.00030905"
                ixy="-1.1347E-09"
                ixz="1.5187E-10"
                iyy="0.00027065"
                iyz="-2.1562E-07"
                izz="0.00022547" />
        </inertial>
        <visual>
            <origin
                xyz="0 0 0"
                rpy="0 0 0" />
            <geometry>
                <mesh
                filename="package://nova5/meshes/gripper/gripper_base_link.STL" />
            </geometry>
            <material name="">
                <color
                    rgba="0.79216 0.81961 0.93333 1" />
            </material>
        </visual>
        <collision>
            <origin
                xyz="0 0 0"
                rpy="0 0 0" />
            <geometry>
                <mesh
                filename="package://nova5/meshes/gripper/gripper_base_link.STL" />
            </geometry>
            <geometry>
                <cylinder radius="0.0375" length="0.1055"/>
            </geometry>
        </collision>
    </link>


    <link name="gripper_link_1">
        <inertial>
            <origin
                xyz="0.0022142 0.00012014 -0.0066966"
                rpy="0 0 0" />
            <mass
                value="0.003116" />
            <inertia
                ixx="4.9277E-08"
                ixy="-7.6567E-11"
                ixz="2.8454E-09"
                iyy="4.7361E-07"
                iyz="5.4464E-10"
                izz="4.6095E-07" />
        </inertial>
            
        
        <visual>
            <origin
                xyz="0 0 0"
                rpy="0 0 0" />
            <geometry>
                <mesh
                    filename="package://nova5/meshes/gripper/gripper_link_1.STL" /> 
            </geometry>
            
            <material
                name="">
                <color
                rgba="0.79216 0.81961 0.93333 1" />
            </material>
        </visual>

        <visual>
            <origin
                xyz="0 0 0"
                rpy="0 0 0" />
            <geometry>
                <mesh
                    filename="package://nova5/meshes/gripper/gripper_link_1_finger.STL" />
            </geometry>
            
            <material
                name="">
                <color
                rgba="0.79216 0.81961 0.93333 1" />
            </material>
        </visual>
        <collision>
            <origin
                xyz="0 0 0"
                rpy="0 0 0" />
            <geometry>
                <mesh
                filename="package://nova5/meshes/gripper/gripper_link_1_finger.STL" />
            </geometry>
        </collision>
    </link>
    <joint
        name="gripper_joint_1"
        type="prismatic">
        <origin
            xyz="-0.00895 -0.017166 0.1075"
            rpy="0 0 1.5708" />
        <parent
            link="gripper_base_link" />
        <child
            link="gripper_link_1" />
        <axis
            xyz="1 0 0" />
        <limit
            lower="0"
            upper="0.026445"
            effort="0"
            velocity="0" />
    </joint>



    <link name="gripper_link_2">
        <inertial>
            <origin
                xyz="0.0022142 0.00012014 -0.0066966"
                rpy="0 0 0" />
            <mass
                value="0.003116" />
            <inertia
                ixx="4.9277E-08"
                ixy="-7.6567E-11"
                ixz="2.8454E-09"
                iyy="4.7361E-07"
                iyz="5.4464E-10"
                izz="4.6095E-07" />
        </inertial>
        <visual>
            <origin
                xyz="0 0 0"
                rpy="0 0 0" />
            <geometry>
                <mesh
                filename="package://nova5/meshes/gripper/gripper_link_2.STL" />
            </geometry>
            <material
                name="">
                <color
                rgba="0.79216 0.81961 0.93333 1" />
            </material>
        </visual>
        <visual>
            <origin
                xyz="0 0 0"
                rpy="0 0 0" />
            <geometry>
                <mesh
                    filename="package://nova5/meshes/gripper/gripper_link_2_finger.STL" />
            </geometry>
            
            <material
                name="">
                <color
                rgba="0.79216 0.81961 0.93333 1" />
            </material>
        </visual>
        <collision>
            <origin
                xyz="0 0 0"
                rpy="0 0 0" />
            <geometry>
                <mesh
                filename="package://nova5/meshes/gripper/gripper_link_2_finger.STL" />
            </geometry>
        </collision>
    </link>
    <joint
        name="gripper_joint_2"
        type="prismatic">
        <origin
            xyz="0.00895 0.017166 0.1075"
            rpy="0 0 -1.5708" />
        <parent
            link="gripper_base_link" />
        <child
            link="gripper_link_2" />
        <axis
            xyz="1 0 0" />
        <limit
            lower="0"
            upper="0.026445"
            effort="0"
            velocity="0" />

        <mimic joint="gripper_joint_1" multiplier="1" offset="0" />
    </joint>

    <link name="grip_link"> 
    </link>
    <joint
        name="grip_joint"
        type="fixed">
        <origin
            xyz="0 0 0.17406"
            rpy="0 0 0" />
        <parent
            link="gripper_base_link" />
        <child
            link="grip_link" />
    </joint>
</robot>